Workbook

Sheet Inventario
A1: # | B1: Equipo | C1: Código lab | D1: Marca | E1: Modelo | F1: Año | G1: N° inventario | H1: Estado | I1: Observaciones | J1: Fecha
A2: =IF(B2="","",ROW()-1) -> 1 | B2: Osciloscopio digital | C2: OSC-0340 | D2: Tektronix | E2: TDS 2022C | F2: 2010 | G2: N00162254 | H2: Sin revisar
A3: =IF(B3="","",ROW()-1) -> 2 | B3: Osciloscopio digital | C3: OSC-0338 | D3: Tektronix | E3: TDS 2022C | F3: 2010 | G3: N00162256 | H3: Sin revisar
A4: =IF(B4="","",ROW()-1) -> 3 | B4: Osciloscopio digital | C4: OSC-0335 | D4: Tektronix | E4: TDS 2022C | F4: 2010 | G4: N00154084 | H4: Sin revisar
A5: =IF(B5="","",ROW()-1) -> 4 | B5: Osciloscopio digital | C5: OSC-0328 | D5: Tektronix | E5: TDS 2022C | F5: 2010 | G5: N00123035 | H5: Sin revisar
A6: =IF(B6="","",ROW()-1) -> 5 | B6: Osciloscopio digital | C6: OSC-0345 | D6: Hantek | E6: DSO2D10 | F6: 2020 | G6: 438194 | H6: Sin revisar
A7: =IF(B7="","",ROW()-1) -> 6 | B7: Osciloscopio digital | C7: OSC-0329 | D7: Tektronix | E7: TDS 2022B | F7: 2005 | G7: N00123036 | H7: Sin revisar
A8: =IF(B8="","",ROW()-1) -> 7 | B8: Osciloscopio digital | C8: OSC-0333 | D8: Tektronix | E8: TDS 2022C | F8: 2010 | G8: N00154085 | H8: Sin revisar
A9: =IF(B9="","",ROW()-1) -> 8 | B9: Osciloscopio digital | C9: OSC-0343 | D9: WELLZION | E9: SmartDS 8202 | F9: 2011 | G9: N00172765 | H9: Sin revisar
A10: =IF(B10="","",ROW()-1) -> 9 | B10: Osciloscopio digital | C10: OSC-0330 | D10: Tektronix | E10: TDS 2022C | F10: 2010 | G10: N00148960 | H10: Sin revisar
A11: =IF(B11="","",ROW()-1) -> 10 | B11: Osciloscopio digital | C11: OSC-0342 | D11: Tektronix | E11: TDS 2022C | F11: 2010 | G11: N00169079 | H11: Sin revisar
A12: =IF(B12="","",ROW()-1) -> 11 | B12: Osciloscopio digital | C12: OSC-0326 | D12: Tektronix | E12: TDS 2022C | F12: 2010 | G12: N00162257 | H12: Sin revisar
A13: =IF(B13="","",ROW()-1) -> 12 | B13: Osciloscopio digital | C13: OSC-0337 | D13: Tektronix | E13: TDS 2022C | F13: 2010 | G13: N00162255 | H13: Sin revisar
A14: =IF(B14="","",ROW()-1) -> 13 | B14: Osciloscopio digital | C14: OSC-0327 | D14: Tektronix | E14: TDS 2022B | F14: 2005 | G14: N00123034 | H14: Sin revisar
A15: =IF(B15="","",ROW()-1) -> 14 | B15: Osciloscopio digital | C15: OSC-0334 | D15: Tektronix | E15: TDS 2022C | F15: 2010 | G15: N00154083 | H15: Sin revisar
A16: =IF(B16="","",ROW()-1) -> 15 | B16: Osciloscopio digital | C16: OSC-0339 | D16: Tektronix | E16: TDS 2022C | F16: 2010 | G16: N00162253 | H16: No funciona | I16: FALLA EN PANTALLA
A17: =IF(B17="","",ROW()-1) -> 16 | B17: Osciloscopio digital | C17: OSC-0341 | D17: Tektronix | E17: TDS 2022C | F17: 2010 | G17: N00169070 | H17: Sin revisar
A18: =IF(B18="","",ROW()-1) -> 17 | B18: Osciloscopio digital | C18: OSC-0344
A19: =IF(B19="","",ROW()-1) -> 18 | B19: Osciloscopio digital | C19: OSC-0324
A20: =IF(B20="","",ROW()-1) -> 19 | B20: Osciloscopio digital | C20: OSC-0307
A21: =IF(B21="","",ROW()-1) -> 20 | B21: Osciloscopio digital | C21: OSC-0331 | D21: Tektronix | E21: TDS 2022C | F21: 2010 | G21: N00148959 | H21: Sin revisar
A22: =IF(B22="","",ROW()-1) -> 21 | B22: Osciloscopio digital | C22: OSC-0306 | D22: HP | E22: 54602B | F22: 1994 | G22: 00-S84551 | H22: Funciona bien
A23: =IF(B23="","",ROW()-1) -> 22 | B23: Osciloscopio analógico | C23: OSC-037 | D23: HITACHI | E23: V-552 | F23: 2000 | G23: 00-42140 | H23: Funciona bien | J23: 46307
A24: =IF(B24="","",ROW()-1) -> 23 | B24: Osciloscopio analógico | C24: OSC-0302 | D24: GoldStar | E24: OS-7040A | F24: 1997 | G24: 00-75870 | H24: Funciona bien | J24: 46307
A25: =IF(B25="","",ROW()-1) -> 24 | B25: Osciloscopio analógico | C25: OSC-0303 | D25: GoldStar | E25: OS-7040A | F25: 2000 | G25: 00-42141 | H25: Funciona bien | J25: 46307
A26: =IF(B26="","",ROW()-1) -> 25 | B26: Osciloscopio analógico | C26: OSC-0316 | D26: BK Precision | E26: 2120B | F26: 2000 | G26: N00050783 | H26: Funciona bien | J26: 46307
A27: =IF(B27="","",ROW()-1) -> 26 | B27: Osciloscopio analógico | C27: OSC-0315 | D27: BK Precision | E27: 2120B | F27: 2000 | G27: N00050785 | H27: Funciona bien | J27: 46307
A28: =IF(B28="","",ROW()-1) -> 27 | B28: Osciloscopio analógico | C28: OSC-0313 | D28: BK Precision | E28: 2120B | F28: 2000 | G28: N00050781 | H28: Funciona bien | J28: 46307
A29: =IF(B29="","",ROW()-1) -> 28 | B29: Osciloscopio analógico | C29: OSC-0318 | D29: BK Precision | E29: 2120B | F29: 2000 | G29: N00103430 | H29: Funciona bien | J29: 46307
A30: =IF(B30="","",ROW()-1) -> 29 | B30: Osciloscopio analógico | C30: OSC-0314 | D30: BK Precision | E30: 2120B | F30: 2000 | G30: N00050780 | H30: Funciona bien | J30: 46307
A31: =IF(B31="","",ROW()-1) -> 30 | B31: Osciloscopio analógico | C31: OSC-0322 | D31: BK Precision | E31: 2120B | F31: 2000 | G31: N00103434 | H31: Funciona bien | J31: 46307
A32: =IF(B32="","",ROW()-1) -> 31 | B32: Osciloscopio analógico | C32: OSC-0317 | D32: BK Precision | E32: 2120B | F32: 2000 | G32: N00103429 | H32: Funciona bien | J32: 46307
A33: =IF(B33="","",ROW()-1) -> 32 | B33: Osciloscopio analógico | C33: OSC-0308 | D33: BK Precision | E33: 2120B | F33: 2000 | G33: N00050777 | H33: Funciona bien | J33: 46307
A34: =IF(B34="","",ROW()-1) -> 33 | B34: Osciloscopio analógico | C34: OSC-0323 | D34: BK Precision | E34: 2120B | F34: 2000 | G34: N00103435 | H34: Funciona bien | J34: 46307
A35: =IF(B35="","",ROW()-1) -> 34 | B35: Osciloscopio analógico | C35: OSC-0309 | D35: BK Precision | E35: 2120B | F35: 2000 | G35: N00050775 | H35: No funciona | I35: DUAL PERMANENTE
A36: =IF(B36="","",ROW()-1) -> 35 | B36: Osciloscopio analógico | C36: OSC-0320 | D36: BK Precision | E36: 2120B | F36: 2000 | G36: N00103432 | H36: No funciona | I36: NO ENCIENDE | J36: 46307
A37: =IF(B37="","",ROW()-1) -> 36 | B37: Osciloscopio analógico | C37: OSC-0311 | D37: BK Precision | E37: 2120B | F37: 2000 | G37: N00050784 | H37: No funciona | I37: NO ENCIENDE | J37: 46307
A38: =IF(B38="","",ROW()-1) -> 37 | B38: Osciloscopio analógico | C38: OSC-0305 | D38: HITACHI | E38: V-552 | F38: 1997 | H38: Funciona bien | J38: 46307
A39: =IF(B39="","",ROW()-1) -> 38 | B39: Osciloscopio analógico | C39: OSC-0321 | D39: BK Precision | E39: 2120B | F39: 2000 | G39: N000103433 | H39: Funciona bien | J39: 46307
A40: =IF(B40="","",ROW()-1) -> 39 | B40: Osciloscopio analógico | C40: OSC-0319 | D40: BK Precision | E40: 2120B | F40: 2000 | G40: N000103431 | H40: Funciona bien | J40: 46307
...

Sheet Resumen
A1: Categoría | B1: Total | C1: Funciona bien | D1: Funciona parcialmente | E1: No funciona | F1: Sin revisar
A2: Osciloscopio digital | B2: =COUNTIFS(Inventario!$B$2:$B$102,$A2,Inventario!$D$2:$D$102,"<>") -> 18 | C2: =COUNTIFS(Inventario!$B$2:$B$102,$A2,Inventario!$H$2:$H$102,C$1,Inventario!$D$2:$D$102,"<>") -> 1 | D2: =COUNTIFS(Inventario!$B$2:$B$102,$A2,Inventario!$H$2:$H$102,D$1,Inventario!$D$2:$D$102,"<>") -> 0 | E2: =COUNTIFS(Inventario!$B$2:$B$102,$A2,Inventario!$H$2:$H$102,E$1,Inventario!$D$2:$D$102,"<>") -> 1 | F2: =COUNTIFS(Inventario!$B$2:$B$102,$A2,Inventario!$H$2:$H$102,F$1,Inventario!$D$2:$D$102,"<>") -> 16
A3: Osciloscopio analógico | B3: =COUNTIFS(Inventario!$B$2:$B$102,$A3,Inventario!$D$2:$D$102,"<>") -> 18 | C3: =COUNTIFS(Inventario!$B$2:$B$102,$A3,Inventario!$H$2:$H$102,C$1,Inventario!$D$2:$D$102,"<>") -> 15 | D3: =COUNTIFS(Inventario!$B$2:$B$102,$A3,Inventario!$H$2:$H$102,D$1,Inventario!$D$2:$D$102,"<>") -> 0 | E3: =COUNTIFS(Inventario!$B$2:$B$102,$A3,Inventario!$H$2:$H$102,E$1,Inventario!$D$2:$D$102,"<>") -> 3 | F3: =COUNTIFS(Inventario!$B$2:$B$102,$A3,Inventario!$H$2:$H$102,F$1,Inventario!$D$2:$D$102,"<>") -> 0
A4: Generador de funciones digital | B4: =COUNTIFS(Inventario!$B$2:$B$102,$A4,Inventario!$D$2:$D$102,"<>") -> 18 | C4: =COUNTIFS(Inventario!$B$2:$B$102,$A4,Inventario!$H$2:$H$102,C$1,Inventario!$D$2:$D$102,"<>") -> 10 | D4: =COUNTIFS(Inventario!$B$2:$B$102,$A4,Inventario!$H$2:$H$102,D$1,Inventario!$D$2:$D$102,"<>") -> 2 | E4: =COUNTIFS(Inventario!$B$2:$B$102,$A4,Inventario!$H$2:$H$102,E$1,Inventario!$D$2:$D$102,"<>") -> 6 | F4: =COUNTIFS(Inventario!$B$2:$B$102,$A4,Inventario!$H$2:$H$102,F$1,Inventario!$D$2:$D$102,"<>") -> 0
A5: Generador de funciones analógico | B5: =COUNTIFS(Inventario!$B$2:$B$102,$A5,Inventario!$D$2:$D$102,"<>") -> 10 | C5: =COUNTIFS(Inventario!$B$2:$B$102,$A5,Inventario!$H$2:$H$102,C$1,Inventario!$D$2:$D$102,"<>") -> 7 | D5: =COUNTIFS(Inventario!$B$2:$B$102,$A5,Inventario!$H$2:$H$102,D$1,Inventario!$D$2:$D$102,"<>") -> 1 | E5: =COUNTIFS(Inventario!$B$2:$B$102,$A5,Inventario!$H$2:$H$102,E$1,Inventario!$D$2:$D$102,"<>") -> 2 | F5: =COUNTIFS(Inventario!$B$2:$B$102,$A5,Inventario!$H$2:$H$102,F$1,Inventario!$D$2:$D$102,"<>") -> 0
A6: Fuente de alimentación | B6: =COUNTIFS(Inventario!$B$2:$B$102,$A6,Inventario!$D$2:$D$102,"<>") -> 14 | C6: =COUNTIFS(Inventario!$B$2:$B$102,$A6,Inventario!$H$2:$H$102,C$1,Inventario!$D$2:$D$102,"<>") -> 10 | D6: =COUNTIFS(Inventario!$B$2:$B$102,$A6,Inventario!$H$2:$H$102,D$1,Inventario!$D$2:$D$102,"<>") -> 0 | E6: =COUNTIFS(Inventario!$B$2:$B$102,$A6,Inventario!$H$2:$H$102,E$1,Inventario!$D$2:$D$102,"<>") -> 4 | F6: =COUNTIFS(Inventario!$B$2:$B$102,$A6,Inventario!$H$2:$H$102,F$1,Inventario!$D$2:$D$102,"<>") -> 0
A7: Multímetro | B7: =COUNTIFS(Inventario!$B$2:$B$102,$A7,Inventario!$D$2:$D$102,"<>") -> 18 | C7: =COUNTIFS(Inventario!$B$2:$B$102,$A7,Inventario!$H$2:$H$102,C$1,Inventario!$D$2:$D$102,"<>") -> 9 | D7: =COUNTIFS(Inventario!$B$2:$B$102,$A7,Inventario!$H$2:$H$102,D$1,Inventario!$D$2:$D$102,"<>") -> 6 | E7: =COUNTIFS(Inventario!$B$2:$B$102,$A7,Inventario!$H$2:$H$102,E$1,Inventario!$D$2:$D$102,"<>") -> 3 | F7: =COUNTIFS(Inventario!$B$2:$B$102,$A7,Inventario!$H$2:$H$102,F$1,Inventario!$D$2:$D$102,"<>") -> 0
A8: TOTAL | B8: =SUM(B2:B7) -> 96 | C8: =SUM(C2:C7) -> 52 | D8: =SUM(D2:D7) -> 9 | E8: =SUM(E2:E7) -> 19 | F8: =SUM(F2:F7) -> 16
A10: Solo cuenta filas con Marca llena (las filas vacías de plantilla no cuentan).
